Workbook

Sheet Task1
B3: Column Labels
B4: Facebook | E4: Instagram | H4: Twitter | K4: Youtube | N4: Total Sum of Likes | O4: Total Sum of Shares | P4: Total Sum of Comments
A5: Row Labels | B5: Sum of Likes | C5: Sum of Shares | D5: Sum of Comments | E5: Sum of Likes | F5: Sum of Shares | G5: Sum of Comments | H5: Sum of Likes | I5: Sum of Shares | J5: Sum of Comments | K5: Sum of Likes | L5: Sum of Shares | M5: Sum of Comments
A6: Carousel | B6: 44476 | C6: 7400 | D6: 4589 | E6: 43948 | F6: 6975 | G6: 3890 | H6: 48649 | I6: 5791 | J6: 3607 | K6: 24926 | L6: 6305 | M6: 2422 | N6: 161999 | O6: 26471 | P6: 14508
A7: Image | B7: 71602 | C7: 12904 | D7: 6495 | E7: 34202 | F7: 5286 | G7: 2655 | H7: 43761 | I7: 7110 | J7: 5125 | K7: 23903 | L7: 4310 | M7: 2077 | N7: 173468 | O7: 29610 | P7: 16352
A8: Reel | B8: 36368 | C8: 5964 | D8: 3353 | E8: 32148 | F8: 8110 | G8: 3386 | H8: 27029 | I8: 4550 | J8: 1913 | K8: 32400 | L8: 4577 | M8: 2668 | N8: 127945 | O8: 23201 | P8: 11320
A9: Story | B9: 29405 | C9: 4950 | D9: 3223 | E9: 42649 | F9: 10049 | G9: 3846 | H9: 20466 | I9: 5090 | J9: 3026 | K9: 31968 | L9: 3866 | M9: 2012 | N9: 124488 | O9: 23955 | P9: 12107
A10: Text | B10: 31963 | C10: 4792 | D10: 3377 | E10: 25567 | F10: 5112 | G10: 1946 | H10: 31899 | I10: 4861 | J10: 3910 | K10: 27067 | L10: 3928 | M10: 1052 | N10: 116496 | O10: 18693 | P10: 10285
A11: Video | B11: 28947 | C11: 3171 | D11: 2263 | E11: 25770 | F11: 5912 | G11: 2128 | H11: 29593 | I11: 6326 | J11: 3299 | K11: 31285 | L11: 5586 | M11: 2589 | N11: 115595 | O11: 20995 | P11: 10279
A12: Grand Total | B12: 242761 | C12: 39181 | D12: 23300 | E12: 204284 | F12: 41444 | G12: 17851 | H12: 201397 | I12: 33728 | J12: 20880 | K12: 171549 | L12: 28572 | M12: 12820 | N12: 819991 | O12: 142925 | P12: 74851

Sheet Task2
A3: Row Labels | B3: Average of Clicks
A4: #EVRevolution | B4: 152.86598
A5: #FutureOfDriving | B5: 144.03883
A6: #TeslaCoInnovation | B6: 157.02
A7: Grand Total | B7: 151.22

Sheet Task3
A1: Row Labels | B1: Sum of Engagement Rate
A2: Facebook | B2: 88.586848
A3: Instagram | B3: 287.25032
A4: Twitter | B4: 287.22914
A5: Youtube | B5: 66.155868
A6: Grand Total | B6: 729.22218
A15: Max of Total_Followers | B15: Column Labels
A16: Row Labels | B16: Facebook | C16: Instagram | D16: Twitter | E16: YouTube | F16: Grand Total
A17: 2024-06-03 | B17: 42654 | C17: 344084 | D17: 146834 | E17: 395536 | F17: 395536
A18: 2024-06-10 | B18: 316555 | C18: 49157 | D18: 254347 | E18: 413878 | F18: 413878
A19: 2024-06-17 | B19: 169496 | C19: 456946 | D19: 122732 | E19: 382851 | F19: 456946
A20: 2024-06-24 | B20: 26295 | C20: 35664 | D20: 298421 | E20: 426184 | F20: 426184
A21: 2024-07-01 | B21: 220020 | C21: 419447 | D21: 315305 | E21: 113678 | F21: 419447
A22: 2024-07-08 | B22: 251694 | C22: 58223 | D22: 389810 | E22: 233694 | F22: 389810
A23: 2024-07-15 | B23: 334626 | C23: 154169 | D23: 226002 | E23: 156683 | F23: 334626
A24: 2024-07-22 | B24: 295032 | C24: 473812 | D24: 198278 | E24: 306564 | F24: 473812
A25: 2024-07-29 | B25: 435034 | C25: 23664 | D25: 287574 | E25: 62499 | F25: 435034
A26: 2024-08-05 | B26: 125034 | C26: 437968 | D26: 449994 | E26: 320650 | F26: 449994
A27: 2024-08-12 | B27: 307612 | C27: 489188 | D27: 434883 | E27: 102042 | F27: 489188
A28: 2024-08-19 | B28: 183924 | C28: 325444 | D28: 188655 | E28: 87443 | F28: 325444
... A67: Grand Total | B67: 496982 | C67: 489188 | D67: 487896 | E67: 488901 | F67: 496982
A71: Row Labels | B71: Sum of Engagement_Rate | C71: Sum of Ad_Spend
A72: Facebook | B72: 282.43 | C72: 1379539
A73: Instagram | B73: 285.78 | C73: 1164373
A74: Twitter | B74: 282.79 | C74: 1060357
A75: YouTube | B75: 277.94 | C75: 1228647
A76: Grand Total | B76: 1128.94 | C76: 4832916

Sheet Task4
A2: Row Labels | B2: Count of Post ID
A3: #TeslaCoInnovation | B3: 100
A4: #FutureOfDriving | B4: 103
A5: #EVRevolution | B5: 97
A6: Grand Total | B6: 300
A20: Row Labels | B20: Sum of Engagement Rate
A21: #EVRevolution | B21: 300.03461
A22: #FutureOfDriving | B22: 113.01987
A23: #TeslaCoInnovation | B23: 316.16771
A24: Grand Total | B24: 729.22218
A40: Sum of Engagement Rate | B40: Column Labels
A41: Row Labels | B41: Facebook | C41: Instagram | D41: Twitter | E41: Youtube | F41: Grand Total
A42: Carousel | B42: 14.622724 | C42: 18.281643 | D42: 219.20597 | E42: 15.348826 | F42: 267.45916
A43: Image | B43: 26.906155 | C43: 10.910512 | D43: 21.075258 | E43: 10.116999 | F43: 69.008923
A44: Reel | B44: 11.428935 | C44: 19.193332 | D44: 11.914006 | E44: 12.658591 | F44: 55.194865
A45: Story | B45: 12.066521 | C45: 213.65871 | D45: 10.690697 | E45: 9.2629124 | F45: 245.67884
A46: Text | B46: 13.777163 | C46: 10.818 | D46: 11.589169 | E46: 8.2910698 | F46: 44.475401
A47: Video | B47: 9.7853501 | C47: 14.388125 | D47: 12.754043 | E47: 10.47747 | F47: 47.404988
A48: Grand Total | B48: 88.586848 | C48: 287.25032 | D48: 287.22914 | E48: 66.155868 | F48: 729.22218

Sheet Task6
A2: Sum of New_Followers | B2: Column Labels
A3: Row Labels | B3: Facebook | C3: Instagram | D3: Twitter | E3: YouTube | F3: Grand Total
A4: 2024-06-03 | B4: 1312 | C4: 1135 | D4: 584 | E4: 1535 | F4: 4566
A5: 2024-06-10 | B5: 1697 | C5: 656 | D5: 436 | E5: 1197 | F5: 3986
A6: 2024-06-17 | B6: 1753 | C6: 1048 | D6: 1335 | E6: 403 | F6: 4539
A7: 2024-06-24 | B7: 1779 | C7: 911 | D7: 1238 | E7: 308 | F7: 4236
A8: 2024-07-01 | B8: 505 | C8: 226 | D8: 1420 | E8: 144 | F8: 2295
A9: 2024-07-08 | B9: 350 | C9: 1757 | D9: 987 | E9: 883 | F9: 3977
A10: 2024-07-15 | B10: 170 | C10: 1960 | D10: 704 | E10: 224 | F10: 3058
A11: 2024-07-22 | B11: 1391 | C11: 508 | D11: 1701 | E11: 804 | F11: 4404
A12: 2024-07-29 | B12: 160 | C12: 653 | D12: 1756 | E12: 576 | F12: 3145
A13: 2024-08-05 | B13: 214 | C13: 645 | D13: 826 | E13: 460 | F13: 2145
A14: 2024-08-12 | B14: 1534 | C14: 1528 | D14: 485 | E14: 1210 | F14: 4757
A15: 2024-08-19 | B15: 1078 | C15: 215 | D15: 1751 | E15: 221 | F15: 3265
... A54: Grand Total | B54: 50862 | C54: 58311 | D54: 53484 | E54: 47471 | F54: 210128

Sheet Posts
A1: Post ID | B1: Clean Platform | C1: Date | D1: Content Type | E1: Post Text | F1: Likes | G1: Shares | H1: Comments | I1: Impressions | J1: Reach | K1: Clicks | L1: Hashtags Used | M1: Hashtags used2 | N1: Engagement Rate | P1: Campaign Name
A2: P279 | B2: Youtube | C2: 2024-09-02 | D2: Image | E2: Check out our latest image on youtube! | F2: 4905 | G2: 845 | H2: 129 | I2: 98100 | J2: 97772 | K2: 279 | L2: #TeslaCoInnovation | N2: 1.0133167 | P2: =IF(AND(C2 >= 'Campaign Metadata'!B$2, C2 <= 'Campaign Metadata'!C$2), 'Campaign Metadata'!A$2, IF(AND(C2 >= 'Campaign Metadata'!B$3, C2 <= 'Campaign Metadata'!C$3), 'Campaign Metadata'!A$3, IF(AND(C2 >= 'Campaign Metadata'!B$4, C2 <= 'Campaign Metadata'!C$4), 'Campaign Metadata'!A$4, IF(AND(C2 >= 'Campaign Metadata'!B$5, C2 <= 'Campaign Metadata'!C$5), 'Campaign Metadata'!A$5, "No Campaign")))) -> No Campaign
A3: P144 | B3: Youtube | C3: 2024-10-28 | D3: Story | E3: Check out our latest story on youtube! | F3: 4929 | G3: 749 | H3: 452 | I3: 93651 | J3: 92810 | K3: 66 | L3: #EVRevolution | N3: 1.0220019 | P3: =IF(AND(C3 >= 'Campaign Metadata'!B$2, C3 <= 'Campaign Metadata'!C$2), 'Campaign Metadata'!A$2, IF(AND(C3 >= 'Campaign Metadata'!B$3, C3 <= 'Campaign Metadata'!C$3), 'Campaign Metadata'!A$3, IF(AND(C3 >= 'Campaign Metadata'!B$4, C3 <= 'Campaign Metadata'!C$4), 'Campaign Metadata'!A$4, IF(AND(C3 >= 'Campaign Metadata'!B$5, C3 <= 'Campaign Metadata'!C$5), 'Campaign Metadata'!A$5, "No Campaign")))) -> ModelYCampaign
A4: P217 | B4: Facebook | C4: 2024-12-03 | D4: Image | E4: Check out our latest image on facebook! | F4: 4606 | G4: 931 | H4: 230 | I4: 92120 | J4: 91440 | K4: 56 | L4: #TeslaCoInnovation | N4: 1.0201334 | P4: =IF(AND(C4 >= 'Campaign Metadata'!B$2, C4 <= 'Campaign Metadata'!C$2), 'Campaign Metadata'!A$2, IF(AND(C4 >= 'Campaign Metadata'!B$3, C4 <= 'Campaign Metadata'!C$3), 'Campaign Metadata'!A$3, IF(AND(C4 >= 'Campaign Metadata'!B$4, C4 <= 'Campaign Metadata'!C$4), 'Campaign Metadata'!A$4, IF(AND(C4 >= 'Campaign Metadata'!B$5, C4 <= 'Campaign Metadata'!C$5), 'Campaign Metadata'!A$5, "No Campaign")))) -> No Campaign
A5: P107 | B5: Youtube | C5: 2024-06-21 | D5: Image | E5: Check out our latest image on youtube! | F5: 4832 | G5: 893 | H5: 10 | I5: 91808 | J5: 91296 | K5: 182 | L5: #TeslaCoInnovation | N5: 1.015499 | P5: =IF(AND(C5 >= 'Campaign Metadata'!B$2, C5 <= 'Campaign Metadata'!C$2), 'Campaign Metadata'!A$2, IF(AND(C5 >= 'Campaign Metadata'!B$3, C5 <= 'Campaign Metadata'!C$3), 'Campaign Metadata'!A$3, IF(AND(C5 >= 'Campaign Metadata'!B$4, C5 <= 'Campaign Metadata'!C$4), 'Campaign Metadata'!A$4, IF(AND(C5 >= 'Campaign Metadata'!B$5, C5 <= 'Campaign Metadata'!C$5), 'Campaign Metadata'!A$5, "No Campaign")))) -> CybertruckLaunch
A6: P063 | B6: Twitter | C6: 2024-07-31 | D6: Carousel | E6: Check out our latest carousel on twitter! | F6: 4507 | G6: 217 | H6: 13 | I6: 90140 | J6: 89591 | K6: 125 | L6: #FutureOfDriving | N6: 1.0086951 | P6: =IF(AND(C6 >= 'Campaign Metadata'!B$2, C6 <= 'Campaign Metadata'!C$2), 'Campaign Metadata'!A$2, IF(AND(C6 >= 'Campaign Metadata'!B$3, C6 <= 'Campaign Metadata'!C$3), 'Campaign Metadata'!A$3, IF(AND(C6 >= 'Campaign Metadata'!B$4, C6 <= 'Campaign Metadata'!C$4), 'Campaign Metadata'!A$4, IF(AND(C6 >= 'Campaign Metadata'!B$5, C6 <= 'Campaign Metadata'!C$5), 'Campaign Metadata'!A$5, "No Campaign")))) -> No Campaign
A7: P225 | B7: Twitter | C7: 2024-06-20 | D7: Carousel | E7: Check out our latest carousel on twitter! | F7: 4672 | G7: 325 | H7: 32 | I7: 88768 | J7: 87833 | K7: 118 | L7: #EVRevolution | N7: 1.0147097 | P7: =IF(AND(C7 >= 'Campaign Metadata'!B$2, C7 <= 'Campaign Metadata'!C$2), 'Campaign Metadata'!A$2, IF(AND(C7 >= 'Campaign Metadata'!B$3, C7 <= 'Campaign Metadata'!C$3), 'Campaign Metadata'!A$3, IF(AND(C7 >= 'Campaign Metadata'!B$4, C7 <= 'Campaign Metadata'!C$4), 'Campaign Metadata'!A$4, IF(AND(C7 >= 'Campaign Metadata'!B$5, C7 <= 'Campaign Metadata'!C$5), 'Campaign Metadata'!A$5, "No Campaign")))) -> CybertruckLaunch
A8: P197 | B8: Twitter | C8: 2024-10-22 | D8: Reel | E8: Check out our latest reel on twitter! | F8: 4782 | G8: 721 | H8: 82 | I8: 86076 | J8: 85339 | K8: 19 | L8: #EVRevolution | N8: 1.0180457 | P8: =IF(AND(C8 >= 'Campaign Metadata'!B$2, C8 <= 'Campaign Metadata'!C$2), 'Campaign Metadata'!A$2, IF(AND(C8 >= 'Campaign Metadata'!B$3, C8 <= 'Campaign Metadata'!C$3), 'Campaign Metadata'!A$3, IF(AND(C8 >= 'Campaign Metadata'!B$4, C8 <= 'Campaign Metadata'!C$4), 'Campaign Metadata'!A$4, IF(AND(C8 >= 'Campaign Metadata'!B$5, C8 <= 'Campaign Metadata'!C$5), 'Campaign Metadata'!A$5, "No Campaign")))) -> ModelYCampaign
A9: P298 | B9: Facebook | C9: 2024-10-24 | D9: Image | E9: Check out our latest image on facebook! | F9: 4303 | G9: 451 | H9: 286 | I9: 86060 | J9: 85823 | K9: 14 | L9: #TeslaCoInnovation | N9: 1.0113489 | P9: =IF(AND(C9 >= 'Campaign Metadata'!B$2, C9 <= 'Campaign Metadata'!C$2), 'Campaign Metadata'!A$2, IF(AND(C9 >= 'Campaign Metadata'!B$3, C9 <= 'Campaign Metadata'!C$3), 'Campaign Metadata'!A$3, IF(AND(C9 >= 'Campaign Metadata'!B$4, C9 <= 'Campaign Metadata'!C$4), 'Campaign Metadata'!A$4, IF(AND(C9 >= 'Campaign Metadata'!B$5, C9 <= 'Campaign Metadata'!C$5), 'Campaign Metadata'!A$5, "No Campaign")))) -> ModelYCampaign
A10: P288 | B10: Youtube | C10: 2025-04-17 | D10: Carousel | E10: Check out our latest carousel on youtube! | F10: 4780 | G10: 691 | H10: 380 | I10: 86040 | J10: 85743 | K10: 262 | L10: #FutureOfDriving | N10: 1.0159547 | P10: =IF(AND(C10 >= 'Campaign Metadata'!B$2, C10 <= 'Campaign Metadata'!C$2), 'Campaign Metadata'!A$2, IF(AND(C10 >= 'Campaign Metadata'!B$3, C10 <= 'Campaign Metadata'!C$3), 'Campaign Metadata'!A$3, IF(AND(C10 >= 'Campaign Metadata'!B$4, C10 <= 'Campaign Metadata'!C$4), 'Campaign Metadata'!A$4, IF(AND(C10 >= 'Campaign Metadata'!B$5, C10 <= 'Campaign Metadata'!C$5), 'Campaign Metadata'!A$5, "No Campaign")))) -> No Campaign
A11: P150 | B11: Youtube | C11: 2024-08-22 | D11: Carousel | E11: Check out our latest carousel on youtube! | F11: 4295 | G11: 853 | H11: 325 | I11: 85900 | J11: 85788 | K11: 290 | L11: #TeslaCoInnovation | N11: 1.0150371 | P11: =IF(AND(C11 >= 'Campaign Metadata'!B$2, C11 <= 'Campaign Metadata'!C$2), 'Campaign Metadata'!A$2, IF(AND(C11 >= 'Campaign Metadata'!B$3, C11 <= 'Campaign Metadata'!C$3), 'Campaign Metadata'!A$3, IF(AND(C11 >= 'Campaign Metadata'!B$4, C11 <= 'Campaign Metadata'!C$4), 'Campaign Metadata'!A$4, IF(AND(C11 >= 'Campaign Metadata'!B$5, C11 <= 'Campaign Metadata'!C$5), 'Campaign Metadata'!A$5, "No Campaign")))) -> No Campaign
A12: P067 | B12: Facebook | C12: 2025-03-29 | D12: Carousel | E12: Check out our latest carousel on facebook! | F12: 4712 | G12: 568 | H12: 127 | I12: 84816 | J12: 84691 | K12: 100 | L12: #EVRevolution | N12: 1.0096823 | P12: =IF(AND(C12 >= 'Campaign Metadata'!B$2, C12 <= 'Campaign Metadata'!C$2), 'Campaign Metadata'!A$2, IF(AND(C12 >= 'Campaign Metadata'!B$3, C12 <= 'Campaign Metadata'!C$3), 'Campaign Metadata'!A$3, IF(AND(C12 >= 'Campaign Metadata'!B$4, C12 <= 'Campaign Metadata'!C$4), 'Campaign Metadata'!A$4, IF(AND(C12 >= 'Campaign Metadata'!B$5, C12 <= 'Campaign Metadata'!C$5), 'Campaign Metadata'!A$5, "No Campaign")))) -> SustainabilityDrive
A13: P215 | B13: Facebook | C13: 2025-05-06 | D13: Image | E13: Check out our latest image on facebook! | F13: 4872 | G13: 925 | H13: 176 | I13: 82824 | J13: 82543 | K13: 89 | L13: #EVRevolution | N13: 1.0167428 | P13: =IF(AND(C13 >= 'Campaign Metadata'!B$2, C13 <= 'Campaign Metadata'!C$2), 'Campaign Metadata'!A$2, IF(AND(C13 >= 'Campaign Metadata'!B$3, C13 <= 'Campaign Metadata'!C$3), 'Campaign Metadata'!A$3, IF(AND(C13 >= 'Campaign Metadata'!B$4, C13 <= 'Campaign Metadata'!C$4), 'Campaign Metadata'!A$4, IF(AND(C13 >= 'Campaign Metadata'!B$5, C13 <= 'Campaign Metadata'!C$5), 'Campaign Metadata'!A$5, "No Campaign")))) -> No Campaign
... A26: P237 | B26: Instagram | C26: 2024-10-22 | D26: Story | E26: Check out our latest story on instagram! | F26: 3770 | G26: 917 | H26: 129 | I26: 71630 | J26: 71322 | K26: 76 | L26: #FutureOfDriving | N26: 1.0189843 | P26: =IF(AND(C26 >= 'Campaign Metadata'!B$2, C26 <= 'Campaign Metadata'!C$2), 'Campaign Metadata'!A$2, IF(AND(C26 >= 'Campaign Metadata'!B$3, C26 <= 'Campaign Metadata'!C$3), 'Campaign Metadata'!A$3, IF(AND(C26 >= 'Campaign Metadata'!B$4, C26 <= 'Campaign Metadata'!C$4), 'Campaign Metadata'!A$4, IF(AND(C26 >= 'Campaign Metadata'!B$5, C26 <= 'Campaign Metadata'!C$5), 'Campaign Metadata'!A$5, "No Campaign")))) -> ModelYCampaign
A27: P005 | B27: Youtube | C27: 2024-06-26 | D27: Reel | E27: Check out our latest reel on youtube! | F27: 3557 | G27: 687 | H27: 424 | I27: 71140 | J27: 70701 | K27: 224 | L27: #EVRevolution | M27: #TeslaCoInnovation | N27: 1.0219233 | P27: =IF(AND(C27 >= 'Campaign Metadata'!B$2, C27 <= 'Campaign Metadata'!C$2), 'Campaign Metadata'!A$2, IF(AND(C27 >= 'Campaign Metadata'!B$3, C27 <= 'Campaign Metadata'!C$3), 'Campaign Metadata'!A$3, IF(AND(C27 >= 'Campaign Metadata'!B$4, C27 <= 'Campaign Metadata'!C$4), 'Campaign Metadata'!A$4, IF(AND(C27 >= 'Campaign Metadata'!B$5, C27 <= 'Campaign Metadata'!C$5), 'Campaign Metadata'!A$5, "No Campaign")))) -> CybertruckLaunch
A28: P200 | B28: Facebook | C28: 2025-04-07 | D28: Reel | E28: Check out our latest reel on facebook! | F28: 3718 | G28: 385 | H28: 310 | I28: 70642 | J28: 69749 | K28: 233 | L28: #TeslaCoInnovation | N28: 1.0227674 | P28: =IF(AND(C28 >= 'Campaign Metadata'!B$2, C28 <= 'Campaign Metadata'!C$2), 'Campaign Metadata'!A$2, IF(AND(C28 >= 'Campaign Metadata'!B$3, C28 <= 'Campaign Metadata'!C$3), 'Campaign Metadata'!A$3, IF(AND(C28 >= 'Campaign Metadata'!B$4, C28 <= 'Campaign Metadata'!C$4), 'Campaign Metadata'!A$4, IF(AND(C28 >= 'Campaign Metadata'!B$5, C28 <= 'Campaign Metadata'!C$5), 'Campaign Metadata'!A$5, "No Campaign")))) -> No Campaign
A29: P291 | B29: Facebook | C29: 2024-11-06 | D29: Video | E29: Check out our latest video on facebook! | F29: 4663 | G29: 145 | H29: 225 | I29: 69945 | J29: 69596 | K29: 35 | L29: #EVRevolution | N29: 1.0103311 | P29: =IF(AND(C29 >= 'Campaign Metadata'!B$2, C29 <= 'Campaign Metadata'!C$2), 'Campaign Metadata'!A$2, IF(AND(C29 >= 'Campaign Metadata'!B$3, C29 <= 'Campaign Metadata'!C$3), 'Campaign Metadata'!A$3, IF(AND(C29 >= 'Campaign Metadata'!B$4, C29 <= 'Campaign Metadata'!C$4), 'Campaign Metadata'!A$4, IF(AND(C29 >= 'Campaign Metadata'!B$5, C29 <= 'Campaign Metadata'!C$5), 'Campaign Metadata'!A$5, "No Campaign")))) -> No Campaign
A30: P090 | B30: Instagram | C30: 2024-06-03 | D30: Image | E30: Check out our latest image on instagram! | F30: 3861 | G30: 960 | H30: 101 | I30: 69498 | J30: 68817 | K30: 297 | L30: #TeslaCoInnovation | N30: 1.0253135 | P30: =IF(AND(C30 >= 'Campaign Metadata'!B$2, C30 <= 'Campaign Metadata'!C$2), 'Campaign Metadata'!A$2, IF(AND(C30 >= 'Campaign Metadata'!B$3, C30 <= 'Campaign Metadata'!C$3), 'Campaign Metadata'!A$3, IF(AND(C30 >= 'Campaign Metadata'!B$4, C30 <= 'Campaign Metadata'!C$4), 'Campaign Metadata'!A$4, IF(AND(C30 >= 'Campaign Metadata'!B$5, C30 <= 'Campaign Metadata'!C$5), 'Campaign Metadata'!A$5, "No Campaign")))) -> No Campaign
A31: P106 | B31: Instagram | C31: 2025-02-04 | D31: Image | E31: Check out our latest image on instagram! | F31: 4619 | G31: 821 | H31: 499 | I31: 69285 | J31: 69141 | K31: 298 | L31: #TeslaCoInnovation | N31: 1.0211741 | P31: =IF(AND(C31 >= 'Campaign Metadata'!B$2, C31 <= 'Campaign Metadata'!C$2), 'Campaign Metadata'!A$2, IF(AND(C31 >= 'Campaign Metadata'!B$3, C31 <= 'Campaign Metadata'!C$3), 'Campaign Metadata'!A$3, IF(AND(C31 >= 'Campaign Metadata'!B$4, C31 <= 'Campaign Metadata'!C$4), 'Campaign Metadata'!A$4, IF(AND(C31 >= 'Campaign Metadata'!B$5, C31 <= 'Campaign Metadata'!C$5), 'Campaign Metadata'!A$5, "No Campaign")))) -> No Campaign
A32: P250 | B32: Facebook | C32: 2024-06-22 | D32: Reel | E32: Check out our latest reel on facebook! | F32: 3813 | G32: 935 | H32: 274 | I32: 68634 | J32: 68488 | K32: 251 | L32: #FutureOfDriving | N32: 1.0197845 | P32: =IF(AND(C32 >= 'Campaign Metadata'!B$2, C32 <= 'Campaign Metadata'!C$2), 'Campaign Metadata'!A$2, IF(AND(C32 >= 'Campaign Metadata'!B$3, C32 <= 'Campaign Metadata'!C$3), 'Campaign Metadata'!A$3, IF(AND(C32 >= 'Campaign Metadata'!B$4, C32 <= 'Campaign Metadata'!C$4), 'Campaign Metadata'!A$4, IF(AND(C32 >= 'Campaign Metadata'!B$5, C32 <= 'Campaign Metadata'!C$5), 'Campaign Metadata'!A$5, "No Campaign")))) -> CybertruckLaunch
A33: P118 | B33: Facebook | C33: 2024-11-04 | D33: Image | E33: Check out our latest image on facebook! | F33: 4551 | G33: 714 | H33: 207 | I33: 68265 | J33: 67754 | K33: 57 | L33: #FutureOfDriving | N33: 1.0211353 | P33: =IF(AND(C33 >= 'Campaign Metadata'!B$2, C33 <= 'Campaign Metadata'!C$2), 'Campaign Metadata'!A$2, IF(AND(C33 >= 'Campaign Metadata'!B$3, C33 <= 'Campaign Metadata'!C$3), 'Campaign Metadata'!A$3, IF(AND(C33 >= 'Campaign Metadata'!B$4, C33 <= 'Campaign Metadata'!C$4), 'Campaign Metadata'!A$4, IF(AND(C33 >= 'Campaign Metadata'!B$5, C33 <= 'Campaign Metadata'!C$5), 'Campaign Metadata'!A$5, "No Campaign")))) -> No Campaign
A34: P170 | B34: Twitter | C34: 2025-04-28 | D34: Text | E34: Check out our latest text on twitter! | F34: 3577 | G34: 596 | H34: 493 | I34: 67963 | J34: 67839 | K34: 53 | L34: #TeslaCoInnovation | N34: 1.0178806 | P34: =IF(AND(C34 >= 'Campaign Metadata'!B$2, C34 <= 'Campaign Metadata'!C$2), 'Campaign Metadata'!A$2, IF(AND(C34 >= 'Campaign Metadata'!B$3, C34 <= 'Campaign Metadata'!C$3), 'Campaign Metadata'!A$3, IF(AND(C34 >= 'Campaign Metadata'!B$4, C34 <= 'Campaign Metadata'!C$4), 'Campaign Metadata'!A$4, IF(AND(C34 >= 'Campaign Metadata'!B$5, C34 <= 'Campaign Metadata'!C$5), 'Campaign Metadata'!A$5, "No Campaign")))) -> No Campaign
A35: P036 | B35: Instagram | C35: 2025-04-19 | D35: Story | E35: Check out our latest story on instagram! | F35: 4518 | G35: 285 | H35: 383 | I35: 67770 | J35: 67621 | K35: 31 | L35: #EVRevolution | N35: 1.012082 | P35: =IF(AND(C35 >= 'Campaign Metadata'!B$2, C35 <= 'Campaign Metadata'!C$2), 'Campaign Metadata'!A$2, IF(AND(C35 >= 'Campaign Metadata'!B$3, C35 <= 'Campaign Metadata'!C$3), 'Campaign Metadata'!A$3, IF(AND(C35 >= 'Campaign Metadata'!B$4, C35 <= 'Campaign Metadata'!C$4), 'Campaign Metadata'!A$4, IF(AND(C35 >= 'Campaign Metadata'!B$5, C35 <= 'Campaign Metadata'!C$5), 'Campaign Metadata'!A$5, "No Campaign")))) -> No Campaign
A36: P024 | B36: Facebook | C36: 2025-01-23 | D36: Video | E36: Check out our latest video on facebook! | F36: 3961 | G36: 761 | H36: 131 | I36: 67337 | J36: 66615 | K36: 161 | L36: #FutureOfDriving | N36: 1.0242288 | P36: =IF(AND(C36 >= 'Campaign Metadata'!B$2, C36 <= 'Campaign Metadata'!C$2), 'Campaign Metadata'!A$2, IF(AND(C36 >= 'Campaign Metadata'!B$3, C36 <= 'Campaign Metadata'!C$3), 'Campaign Metadata'!A$3, IF(AND(C36 >= 'Campaign Metadata'!B$4, C36 <= 'Campaign Metadata'!C$4), 'Campaign Metadata'!A$4, IF(AND(C36 >= 'Campaign Metadata'!B$5, C36 <= 'Campaign Metadata'!C$5), 'Campaign Metadata'!A$5, "No Campaign")))) -> No Campaign
A37: P267 | B37: Twitter | C37: 2024-10-04 | D37: Reel | E37: Check out our latest reel on twitter! | F37: 4187 | G37: 66 | H37: 31 | I37: 66992 | J37: 66614 | K37: 62 | L37: #FutureOfDriving | N37: 1.0071306 | P37: =IF(AND(C37 >= 'Campaign Metadata'!B$2, C37 <= 'Campaign Metadata'!C$2), 'Campaign Metadata'!A$2, IF(AND(C37 >= 'Campaign Metadata'!B$3, C37 <= 'Campaign Metadata'!C$3), 'Campaign Metadata'!A$3, IF(AND(C37 >= 'Campaign Metadata'!B$4, C37 <= 'Campaign Metadata'!C$4), 'Campaign Metadata'!A$4, IF(AND(C37 >= 'Campaign Metadata'!B$5, C37 <= 'Campaign Metadata'!C$5), 'Campaign Metadata'!A$5, "No Campaign")))) -> ModelYCampaign
A38: P099 | B38: Youtube | C38: 2024-07-02 | D38: Carousel | E38: Check out our latest carousel on youtube! | F38: 4171 | G38: 548 | H38: 86 | I38: 66736 | J38: 66634 | K38: 173 | L38: #FutureOfDriving | N38: 1.0110454 | P38: =IF(AND(C38 >= 'Campaign Metadata'!B$2, C38 <= 'Campaign Metadata'!C$2), 'Campaign Metadata'!A$2, IF(AND(C38 >= 'Campaign Metadata'!B$3, C38 <= 'Campaign Metadata'!C$3), 'Campaign Metadata'!A$3, IF(AND(C38 >= 'Campaign Metadata'!B$4, C38 <= 'Campaign Metadata'!C$4), 'Campaign Metadata'!A$4, IF(AND(C38 >= 'Campaign Metadata'!B$5, C38 <= 'Campaign Metadata'!C$5), 'Campaign Metadata'!A$5, "No Campaign")))) -> CybertruckLaunch
A39: P127 | B39: Facebook | C39: 2025-01-27 | D39: Reel | E39: Check out our latest reel on facebook! | F39: 3452 | G39: 652 | H39: 442 | I39: 65588 | J39: 65049 | K39: 158 | L39: #FutureOfDriving | N39: 1.0251042 | P39: =IF(AND(C39 >= 'Campaign Metadata'!B$2, C39 <= 'Campaign Metadata'!C$2), 'Campaign Metadata'!A$2, IF(AND(C39 >= 'Campaign Metadata'!B$3, C39 <= 'Campaign Metadata'!C$3), 'Campaign Metadata'!A$3, IF(AND(C39 >= 'Campaign Metadata'!B$4, C39 <= 'Campaign Metadata'!C$4), 'Campaign Metadata'!A$4, IF(AND(C39 >= 'Campaign Metadata'!B$5, C39 <= 'Campaign Metadata'!C$5), 'Campaign Metadata'!A$5, "No Campaign")))) -> No Campaign
A40: P002 | B40: Twitter | C40: 2025-04-03 | D40: Text | E40: Check out our latest text on twitter! | F40: 4054 | G40: 389 | H40: 493 | I40: 64864 | J40: 64383 | K40: 117 | L40: #TeslaCoInnovation | M40: #BetterWithTesla | N40: 1.0211702 | P40: =IF(AND(C40 >= 'Campaign Metadata'!B$2, C40 <= 'Campaign Metadata'!C$2), 'Campaign Metadata'!A$2, IF(AND(C40 >= 'Campaign Metadata'!B$3, C40 <= 'Campaign Metadata'!C$3), 'Campaign Metadata'!A$3, IF(AND(C40 >= 'Campaign Metadata'!B$4, C40 <= 'Campaign Metadata'!C$4), 'Campaign Metadata'!A$4, IF(AND(C40 >= 'Campaign Metadata'!B$5, C40 <= 'Campaign Metadata'!C$5), 'Campaign Metadata'!A$5, "No Campaign")))) -> No Campaign
A41: P179 | B41: Facebook | C41: 2024-07-15 | D41: Carousel | E41: Check out our latest carousel on facebook! | F41: 3796 | G41: 667 | H41: 395 | I41: 64532 | J41: 63550 | K41: 292 | L41: #TeslaCoInnovation | N41: 1.0321637 | P41: =IF(AND(C41 >= 'Campaign Metadata'!B$2, C41 <= 'Campaign Metadata'!C$2), 'Campaign Metadata'!A$2, IF(AND(C41 >= 'Campaign Metadata'!B$3, C41 <= 'Campaign Metadata'!C$3), 'Campaign Metadata'!A$3, IF(AND(C41 >= 'Campaign Metadata'!B$4, C41 <= 'Campaign Metadata'!C$4), 'Campaign Metadata'!A$4, IF(AND(C41 >= 'Campaign Metadata'!B$5, C41 <= 'Campaign Metadata'!C$5), 'Campaign Metadata'!A$5, "No Campaign")))) -> CybertruckLaunch
A42: P280 | B42: Youtube | C42: 2024-10-21 | D42: Video | E42: Check out our latest video on youtube! | F42: 4275 | G42: 680 | H42: 385 | I42: 64125 | J42: 63650 | K42: 104 | L42: #EVRevolution | M42: #TeslaCoInnovation | N42: 1.0241948 | P42: =IF(AND(C42 >= 'Campaign Metadata'!B$2, C42 <= 'Campaign Metadata'!C$2), 'Campaign Metadata'!A$2, IF(AND(C42 >= 'Campaign Metadata'!B$3, C42 <= 'Campaign Metadata'!C$3), 'Campaign Metadata'!A$3, IF(AND(C42 >= 'Campaign Metadata'!B$4, C42 <= 'Campaign Metadata'!C$4), 'Campaign Metadata'!A$4, IF(AND(C42 >= 'Campaign Metadata'!B$5, C42 <= 'Campaign Metadata'!C$5), 'Campaign Metadata'!A$5, "No Campaign")))) -> ModelYCampaign
A43: P283 | B43: Twitter | C43: 2025-05-09 | D43: Reel | E43: Check out our latest reel on twitter! | F43: 3367 | G43: 302 | H43: 57 | I43: 63973 | J43: 63789 | K43: 157 | L43: #FutureOfDriving | N43: 1.0085124 | P43: =IF(AND(C43 >= 'Campaign Metadata'!B$2, C43 <= 'Campaign Metadata'!C$2), 'Campaign Metadata'!A$2, IF(AND(C43 >= 'Campaign Metadata'!B$3, C43 <= 'Campaign Metadata'!C$3), 'Campaign Metadata'!A$3, IF(AND(C43 >= 'Campaign Metadata'!B$4, C43 <= 'Campaign Metadata'!C$4), 'Campaign Metadata'!A$4, IF(AND(C43 >= 'Campaign Metadata'!B$5, C43 <= 'Campaign Metadata'!C$5), 'Campaign Metadata'!A$5, "No Campaign")))) -> No Campaign
A44: P300 | B44: Twitter | C44: 2024-08-31 | D44: Carousel | E44: Check out our latest carousel on twitter! | F44: 4494 | G44: 717 | H44: 45 | I44: 62916 | J44: 62688 | K44: 191 | L44: #TeslaCoInnovation | M44: #EVRevolution | N44: 1.0157925 | P44: =IF(AND(C44 >= 'Campaign Metadata'!B$2, C44 <= 'Campaign Metadata'!C$2), 'Campaign Metadata'!A$2, IF(AND(C44 >= 'Campaign Metadata'!B$3, C44 <= 'Campaign Metadata'!C$3), 'Campaign Metadata'!A$3, IF(AND(C44 >= 'Campaign Metadata'!B$4, C44 <= 'Campaign Metadata'!C$4), 'Campaign Metadata'!A$4, IF(AND(C44 >= 'Campaign Metadata'!B$5, C44 <= 'Campaign Metadata'!C$5), 'Campaign Metadata'!A$5, "No Campaign")))) -> No Campaign
A45: P007 | B45: Twitter | C45: 2024-06-24 | D45: Carousel | E45: Check out our latest carousel on twitter! | F45: 3860 | G45: 201 | H45: 279 | I45: 61760 | J45: 61660 | K45: 235 | L45: #TeslaCoInnovation | N45: 1.0094064 | P45: =IF(AND(C45 >= 'Campaign Metadata'!B$2, C45 <= 'Campaign Metadata'!C$2), 'Campaign Metadata'!A$2, IF(AND(C45 >= 'Campaign Metadata'!B$3, C45 <= 'Campaign Metadata'!C$3), 'Campaign Metadata'!A$3, IF(AND(C45 >= 'Campaign Metadata'!B$4, C45 <= 'Campaign Metadata'!C$4), 'Campaign Metadata'!A$4, IF(AND(C45 >= 'Campaign Metadata'!B$5, C45 <= 'Campaign Metadata'!C$5), 'Campaign Metadata'!A$5, "No Campaign")))) -> CybertruckLaunch
A46: P097 | B46: Instagram | C46: 2024-08-13 | D46: Image | E46: Check out our latest image on instagram! | F46: 4739 | G46: 527 | H46: 135 | I46: 61607 | J46: 61333 | K46: 36 | L46: #TeslaCoInnovation | M46: #AnytimeIsTeslaTime | N46: 1.015261 | P46: =IF(AND(C46 >= 'Campaign Metadata'!B$2, C46 <= 'Campaign Metadata'!C$2), 'Campaign Metadata'!A$2, IF(AND(C46 >= 'Campaign Metadata'!B$3, C46 <= 'Campaign Metadata'!C$3), 'Campaign Metadata'!A$3, IF(AND(C46 >= 'Campaign Metadata'!B$4, C46 <= 'Campaign Metadata'!C$4), 'Campaign Metadata'!A$4, IF(AND(C46 >= 'Campaign Metadata'!B$5, C46 <= 'Campaign Metadata'!C$5), 'Campaign Metadata'!A$5, "No Campaign")))) -> No Campaign
A47: P194 | B47: Youtube | C47: 2024-10-02 | D47: Story | E47: Check out our latest story on youtube! | F47: 4350 | G47: 771 | H47: 7 | I47: 60900 | J47: 60592 | K47: 195 | L47: #EVRevolution | N47: 1.0179232 | P47: =IF(AND(C47 >= 'Campaign Metadata'!B$2, C47 <= 'Campaign Metadata'!C$2), 'Campaign Metadata'!A$2, IF(AND(C47 >= 'Campaign Metadata'!B$3, C47 <= 'Campaign Metadata'!C$3), 'Campaign Metadata'!A$3, IF(AND(C47 >= 'Campaign Metadata'!B$4, C47 <= 'Campaign Metadata'!C$4), 'Campaign Metadata'!A$4, IF(AND(C47 >= 'Campaign Metadata'!B$5, C47 <= 'Campaign Metadata'!C$5), 'Campaign Metadata'!A$5, "No Campaign")))) -> ModelYCampaign
A48: P260 | B48: Instagram | C48: 2025-02-12 | D48: Story | E48: Check out our latest story on instagram! | F48: 4332 | G48: 771 | H48: 219 | I48: 60648 | J48: 60397 | K48: 10 | L48: #TeslaCoInnovation | M48: #EVRevolution | N48: 1.0205474 | P48: =IF(AND(C48 >= 'Campaign Metadata'!B$2, C48 <= 'Campaign Metadata'!C$2), 'Campaign Metadata'!A$2, IF(AND(C48 >= 'Campaign Metadata'!B$3, C48 <= 'Campaign Metadata'!C$3), 'Campaign Metadata'!A$3, IF(AND(C48 >= 'Campaign Metadata'!B$4, C48 <= 'Campaign Metadata'!C$4), 'Campaign Metadata'!A$4, IF(AND(C48 >= 'Campaign Metadata'!B$5, C48 <= 'Campaign Metadata'!C$5), 'Campaign Metadata'!A$5, "No Campaign")))) -> No Campaign
A49: P039 | B49: Facebook | C49: 2024-11-25 | D49: Image | E49: Check out our latest image on facebook! | F49: 3564 | G49: 629 | H49: 177 | I49: 60588 | J49: 59627 | K49: 92 | L49: #TeslaCoInnovation | N49: 1.0296342 | P49: =IF(AND(C49 >= 'Campaign Metadata'!B$2, C49 <= 'Campaign Metadata'!C$2), 'Campaign Metadata'!A$2, IF(AND(C49 >= 'Campaign Metadata'!B$3, C49 <= 'Campaign Metadata'!C$3), 'Campaign Metadata'!A$3, IF(AND(C49 >= 'Campaign Metadata'!B$4, C49 <= 'Campaign Metadata'!C$4), 'Campaign Metadata'!A$4, IF(AND(C49 >= 'Campaign Metadata'!B$5, C49 <= 'Campaign Metadata'!C$5), 'Campaign Metadata'!A$5, "No Campaign")))) -> No Campaign
A50: P189 | B50: Facebook | C50: 2025-03-24 | D50: Reel | E50: Check out our latest reel on facebook! | F50: 3360 | G50: 525 | H50: 500 | I50: 60480 | J50: 59610 | K50: 192 | L50: #TeslaCoInnovation | N50: 1.03179 | P50: =IF(AND(C50 >= 'Campaign Metadata'!B$2, C50 <= 'Campaign Metadata'!C$2), 'Campaign Metadata'!A$2, IF(AND(C50 >= 'Campaign Metadata'!B$3, C50 <= 'Campaign Metadata'!C$3), 'Campaign Metadata'!A$3, IF(AND(C50 >= 'Campaign Metadata'!B$4, C50 <= 'Campaign Metadata'!C$4), 'Campaign Metadata'!A$4, IF(AND(C50 >= 'Campaign Metadata'!B$5, C50 <= 'Campaign Metadata'!C$5), 'Campaign Metadata'!A$5, "No Campaign")))) -> SustainabilityDrive
A51: P270 | B51: Youtube | C51: 2025-01-15 | D51: Reel | E51: Check out our latest reel on youtube! | F51: 3774 | G51: 239 | H51: 39 | I51: 60384 | J51: 59490 | K51: 241 | L51: #TeslaCoInnovation | N51: 1.0197008 | P51: =IF(AND(C51 >= 'Campaign Metadata'!B$2, C51 <= 'Campaign Metadata'!C$2), 'Campaign Metadata'!A$2, IF(AND(C51 >= 'Campaign Metadata'!B$3, C51 <= 'Campaign Metadata'!C$3), 'Campaign Metadata'!A$3, IF(AND(C51 >= 'Campaign Metadata'!B$4, C51 <= 'Campaign Metadata'!C$4), 'Campaign Metadata'!A$4, IF(AND(C51 >= 'Campaign Metadata'!B$5, C51 <= 'Campaign Metadata'!C$5), 'Campaign Metadata'!A$5, "No Campaign")))) -> No Campaign
A52: P223 | B52: Twitter | C52: 2024-11-12 | D52: Image | E52: Check out our latest image on twitter! | F52: 3338 | G52: 277 | H52: 118 | I52: 60084 | J52: 59842 | K52: 252 | L52: #TeslaCoInnovation | N52: 1.0106447 | P52: =IF(AND(C52 >= 'Campaign Metadata'!B$2, C52 <= 'Campaign Metadata'!C$2), 'Campaign Metadata'!A$2, IF(AND(C52 >= 'Campaign Metadata'!B$3, C52 <= 'Campaign Metadata'!C$3), 'Campaign Metadata'!A$3, IF(AND(C52 >= 'Campaign Metadata'!B$4, C52 <= 'Campaign Metadata'!C$4), 'Campaign Metadata'!A$4, IF(AND(C52 >= 'Campaign Metadata'!B$5, C52 <= 'Campaign Metadata'!C$5), 'Campaign Metadata'!A$5, "No Campaign")))) -> No Campaign
...

Sheet Campaign analysis Task5
A1: Campaign | B1: Total Impressions | C1: Avg Likes | D1: Avg Engagement Rate | E1: Total Clicks | F1: Total Ad Spend | G1: Total Engagement | H1: ROI (Engagement/$) | I1: Campaign | J1: New Followers Gained
A2: CybertruckLaunch | B2: =SUMIF(Posts!P:P, A2, Posts!J:J) -> 1157851 | C2: =AVERAGEIF(Posts!P:P, A2, Posts!G:G) -> 405.62963 | D2: =AVERAGEIF(Posts!P:P, A2, Posts!N:N) -> 1.0422737 | E2: =SUMIF(Posts!P:P, A2, Posts!K:K) -> 3759 | F2: =SUMIFS('Engagement Summary'!G:G, 'Engagement Summary'!A:A, ">=" & 'Campaign Metadata'!B2, 'Engagement Summary'!A:A, "<=" & 'Campaign Metadata'!C2) -> 468757 | G2: =SUMIF(Posts!P:P, A2, Posts!G:G) + SUMIF(Posts!P:P, A2, Posts!H:H) + SUMIF(Posts!P:P, A2, Posts!I:I) -> 1189097 | H2: =G2/F2 -> 2.5367024 | I2: =SUMIFS('Engagement Summary'!C:C, 'Engagement Summary'!A:A, ">=" & 'Campaign Metadata'!B2, 'Engagement Summary'!A:A, "<=" & 'Campaign Metadata'!C2) -> 18105
A3: ModelYCampaign | B3: =SUMIF(Posts!P:P, A3, Posts!J:J) -> 1463004 | C3: =AVERAGEIF(Posts!P:P, A3, Posts!G:G) -> 593.31429 | D3: =AVERAGEIF(Posts!P:P, A3, Posts!N:N) -> 1.1494607 | E3: =SUMIF(Posts!P:P, A3, Posts!K:K) -> 4629 | F3: =SUMIFS('Engagement Summary'!G:G, 'Engagement Summary'!A:A, ">=" & 'Campaign Metadata'!B3, 'Engagement Summary'!A:A, "<=" & 'Campaign Metadata'!C3) -> 447611 | G3: =SUMIF(Posts!P:P, A3, Posts!G:G) + SUMIF(Posts!P:P, A3, Posts!H:H) + SUMIF(Posts!P:P, A3, Posts!I:I) -> 1510761 | H3: =G3/F3 -> 3.375165 | I3: =SUMIFS('Engagement Summary'!C:C, 'Engagement Summary'!A:A, ">=" & 'Campaign Metadata'!B3, 'Engagement Summary'!A:A, "<=" & 'Campaign Metadata'!C3) -> 14518
A4: FSDUpdate | B4: =SUMIF(Posts!P:P, A4, Posts!J:J) -> 268852 | C4: =AVERAGEIF(Posts!P:P, A4, Posts!G:G) -> 438.9 | D4: =AVERAGEIF(Posts!P:P, A4, Posts!N:N) -> 1.0781053 | E4: =SUMIF(Posts!P:P, A4, Posts!K:K) -> 1056 | F4: =SUMIFS('Engagement Summary'!G:G, 'Engagement Summary'!A:A, ">=" & 'Campaign Metadata'!B4, 'Engagement Summary'!A:A, "<=" & 'Campaign Metadata'!C4) -> 151428 | G4: =SUMIF(Posts!P:P, A4, Posts!G:G) + SUMIF(Posts!P:P, A4, Posts!H:H) + SUMIF(Posts!P:P, A4, Posts!I:I) -> 281116 | H4: =G4/F4 -> 1.8564334 | I4: =SUMIFS('Engagement Summary'!C:C, 'Engagement Summary'!A:A, ">=" & 'Campaign Metadata'!B4, 'Engagement Summary'!A:A, "<=" & 'Campaign Metadata'!C4) -> 11428
A5: SustainabilityDrive | B5: =SUMIF(Posts!P:P, A5, Posts!J:J) -> 1021386 | C5: =AVERAGEIF(Posts!P:P, A5, Posts!G:G) -> 485.96875 | D5: =AVERAGEIF(Posts!P:P, A5, Posts!N:N) -> 1.0788523 | E5: =SUMIF(Posts!P:P, A5, Posts!K:K) -> 5178 | F5: =SUMIFS('Engagement Summary'!G:G, 'Engagement Summary'!A:A, ">=" & 'Campaign Metadata'!B5, 'Engagement Summary'!A:A, "<=" & 'Campaign Metadata'!C5) -> 423771 | G5: =SUMIF(Posts!P:P, A5, Posts!G:G) + SUMIF(Posts!P:P, A5, Posts!H:H) + SUMIF(Posts!P:P, A5, Posts!I:I) -> 1066686 | H5: =G5/F5 -> 2.5171284 | I5: =SUMIFS('Engagement Summary'!C:C, 'Engagement Summary'!A:A, ">=" & 'Campaign Metadata'!B5, 'Engagement Summary'!A:A, "<=" & 'Campaign Metadata'!C5) -> 20682
A10: Campaign | B10: Baseline ER | C10: Campaign ER | D10: Uplift %
A11: CybertruckLaunch | B11: =IFERROR(AVERAGEIFS(Posts!N:N, Posts!C:C, ">=" & DATE(2024,5,18), Posts!C:C, "<" & DATE(2024,6,15)), AVERAGE(Posts!N:N)) -> 2.4307406 | C11: =D2 -> 1.0422737 | D11: =(C11-B11)/B11 -> -0.57121146
A12: ModelYCampaign | B12: =IFERROR(AVERAGEIFS(Posts!N:N, Posts!C:C, ">=" & DATE(2024,9,3), Posts!C:C, "<" & DATE(2024,10,1)), AVERAGE(Posts!N:N)) -> 2.4307406 | C12: =D3 -> 1.1494607 | D12: =(C12-B12)/B12 -> -0.52711504
A13: FSDUpdate | B13: =IFERROR(AVERAGEIFS(Posts!N:N, Posts!C:C, ">=" & DATE(2024,11,27), Posts!C:C, "<" & DATE(2024,12,25)), AVERAGE(Posts!N:N)) -> 2.4307406 | C13: =D4 -> 1.0781053 | D13: =(C13-B13)/B13 -> -0.55647046
A14: SustainabilityDrive | B14: =IFERROR(AVERAGEIFS(Posts!N:N, Posts!C:C, ">=" & DATE(2024,11,27), Posts!C:C, "<" & DATE(2024,12,25)), AVERAGE(Posts!N:N)) -> 2.4307406 | C14: =D5 -> 1.0788523 | D14: =(C14-B14)/B14 -> -0.55616312

Sheet Engagement Summary
A1: Week_Start_Date | B1: Platform | C1: New_Followers | D1: Unfollows | E1: Total_Followers | F1: Engagement_Rate | G1: Ad_Spend
A2: 45446 | B2: Instagram | C2: 1135 | D2: 88 | E2: 344084 | F2: 8.06 | G2: 5904
A3: 45446 | B3: Facebook | C3: 1312 | D3: 310 | E3: 42654 | F3: 4.98 | G3: 9566
A4: 45446 | B4: Twitter | C4: 584 | D4: 169 | E4: 146834 | F4: 8.31 | G4: 26752
A5: 45446 | B5: YouTube | C5: 1535 | D5: 445 | E5: 395536 | F5: 4.11 | G5: 30671
A6: 45453 | B6: Instagram | C6: 656 | D6: 139 | E6: 49157 | F6: 9.05 | G6: 9920
A7: 45453 | B7: Facebook | C7: 1697 | D7: 414 | E7: 316555 | F7: 2.37 | G7: 7924
A8: 45453 | B8: Twitter | C8: 436 | D8: 250 | E8: 254347 | F8: 4.01 | G8: 8912
A9: 45453 | B9: YouTube | C9: 1197 | D9: 203 | E9: 413878 | F9: 3.16 | G9: 21205
A10: 45460 | B10: Instagram | C10: 1048 | D10: 155 | E10: 456946 | F10: 2.46 | G10: 11329
A11: 45460 | B11: Facebook | C11: 1753 | D11: 371 | E11: 169496 | F11: 8.11 | G11: 46670
A12: 45460 | B12: Twitter | C12: 1335 | D12: 40 | E12: 122732 | F12: 8.19 | G12: 22482
A13: 45460 | B13: YouTube | C13: 403 | D13: 66 | E13: 382851 | F13: 3.49 | G13: 24313
... A201: 45789 | B201: YouTube | C201: 119 | D201: 456 | E201: 82558 | F201: 6.81 | G201: 12174

Sheet Campaign Metadata
A1: Campaign_Name | B1: Start_Date | C1: End_Date | D1: Objective | E1: Total_Budget | F1: Target_Platforms | G1: Primary_Hashtags
A2: CybertruckLaunch | B2: 2024-06-15 | C2: 2024-07-15 | D2: Product Awareness | E2: 150000 | F2: Instagram,Facebook | G2: #EVRevolution,#TeslaCoInnovation
A3: ModelYCampaign | B3: 2024-10-01 | C3: 2024-10-31 | D3: Customer Engagement | E3: 200000 | F3: Instagram,YouTube | G3: #AnytimeIsTeslaTime,
A4: FSDUpdate | B4: 2024-12-25 | C4: 2025-01-10 | D4: Vehicle Launch | E4: 250000 | F4: Facebook,Twitter | G4: #SmoothLikeNitroTesla
A5: SustainabilityDrive | B5: 2025-03-01 | C5: 2025-03-31 | D5: Community Growth | E5: 180000 | F5: Instagram,Twitter | G5: #BetterWithTesla,#FutureOfDriving
